<?xml version="1.0"?>

<robot xmlns:xacro="http://www.ros.org/wiki/xacro" name="man_bot_patrolling">

  <xacro:arg name="use_nominal_extrinsics" default="false"/>
  <xacro:arg name="add_plug" default="false" />
  <xacro:arg name="use_mesh" default="true" />


  <xacro:include filename="$(find exprob_robot_patrolling)/urdf/robot_patrolling_explorer.gazebo" />

  <xacro:macro name="cylinder_inertia" params="mass r l"> 
    <inertia ixx="${mass*(3*r*r+l*l)/12}" ixy = "0" ixz = "0"
                iyy="${mass*(3*r*r+l*l)/12}" iyz = "0" izz="${mass*(r*r)/2}" /> 
  </xacro:macro>


  <material name="light_grey">
    <color rgba="0.5 0.5 0.5 1"/>
  </material>
  <material name="dark_grey">
    <color rgba="0.8 0.8 0.8 1"/>
  </material>
  <material name="blue">
    <color rgba="0 0 0.8 1"/>
  </material>
  <material name="white">
    <color rgba="1 1 1 1"/>
  </material>
  
  <!-- Camera -->
  <link name="camera_link">
    <visual>
      <origin xyz="0 0 0" rpy="0 0 0"/>
      <geometry>
        <box size="0.02 0.06 0.02"/>
      </geometry>
      <material name="dark_grey"/>
    </visual>
  
    <inertial>
      <mass value="0.05"/>
      <origin rpy="0 0 0" xyz="0 0 0"/>
      <inertia ixx="0.0395416666667" ixy="0" ixz="0" iyy="0.106208333333" iyz="0" izz="0.106208333333"/>
    </inertial>
  </link>

  


  <link name="rbot_base">
    <visual>
      <geometry>
        <box size="0.045 0.09 0.03"/>
      </geometry>
      <origin rpy="0 0 0" xyz="0 0 0"/>
       <material name="white"/>
    </visual>

    <inertial>
      <mass value="0.1"/>
      <origin rpy="0 0 0" xyz="0 0 0"/>
      <inertia ixx="0.0395416666667" ixy="0" ixz="0" iyy="0.106208333333" iyz="0" izz="0.106208333333"/>
    </inertial>
    <!-- body -->
    <collision name="collision_rbot_base">
      <geometry>
        <box size="0.045 0.09 0.03"/>
      </geometry>
    </collision>
  </link>

  <link name="servo_bottom">
    <visual>
      <geometry>
        <cylinder length="0.05" radius="0.015"/>
      </geometry>
      <origin rpy="0 0 0" xyz="0 0 0"/>
      <material name="blue"/>
    </visual>

    <inertial>
      <origin xyz="0 0 0" rpy="0 0 0" />
      <mass value="0.6" />
      <xacro:cylinder_inertia mass="0.6" r="0.015" l="0.05" />
    </inertial>
    <!-- body -->
    <collision name="collision_servo_bottom">
      <geometry>
        <cylinder length="0.05" radius="0.015"/>
      </geometry>
    </collision>
  </link>

  <link name="U_Link">
    <visual>
      <geometry>
        <box size="0.015 0.03 0.064"/>
      </geometry>
      <origin rpy="0 0 0" xyz="0 0 0"/>
      <material name="white"/>
    </visual>

    <inertial>
      <mass value="0.1"/>
      <origin rpy="0 0 0" xyz="0 0 0"/>
      <inertia ixx="0.0395416666667" ixy="0" ixz="0" iyy="0.106208333333" iyz="0" izz="0.106208333333"/>
    </inertial>
    <!-- body -->
    <collision name="collision_U_link">
      <geometry>
        <box size="0.015 0.03 0.064"/>
      </geometry>
    </collision>
  </link>

  <link name="servo_mid">
    <visual>
      <geometry>
        <cylinder length="0.05" radius="0.015"/>
      </geometry>
      <origin rpy="1.57 0 0" xyz="0 0 0"/>
      <material name="blue"/>
    </visual>

    <inertial>
      <origin xyz="0 0 0" rpy="0 0 0" />
      <mass value="0.6" />
      <xacro:cylinder_inertia mass="0.6" r="0.015" l="0.05" />
    </inertial>
    <!-- body -->
    <collision name="collision_servo_mid">
      <geometry>
        <cylinder length="0.05" radius="0.015"/>
      </geometry>
    </collision>
  </link>

  <link name="servo_up">
    <visual>
      <geometry>
        <cylinder length="0.05" radius="0.015"/>
      </geometry>
      <origin rpy="0 0 0" xyz="0 0 0"/>
      <material name="blue"/>
    </visual>

    <inertial>
      <origin xyz="0 0 0" rpy="0 0 0" />
      <mass value="0.6" />
      <xacro:cylinder_inertia mass="0.6" r="0.015" l="0.05" />
    </inertial>
    <!-- body -->
    <collision name="collision_servo_up">
      <geometry>
        <cylinder length="0.05" radius="0.015"/>
      </geometry>
    </collision>
  </link>

  <link name="up_mount">
    <visual>
      <geometry>
        <box size="0.05 0.148 0.05"/>
      </geometry>
      <origin rpy="0 0 0" xyz="0 0 0"/>
      <material name="light_grey"/>
    </visual>

    <inertial>
      <mass value="0.1"/>
      <origin rpy="0 0 0" xyz="0 0 0"/>
      <inertia ixx="0.0395416666667" ixy="0" ixz="0" iyy="0.106208333333" iyz="0" izz="0.106208333333"/>
    </inertial>
    <!-- body -->
    <collision name="collision_up_mount">
      <geometry>
        <box size="0.05 0.148 0.05"/>
      </geometry>
    </collision>
  </link>

  <joint name="base_to_Servo_B" type="fixed">
    <parent link="rbot_base"/>
    <child link="servo_bottom"/>
    <origin xyz="0 0 0.04"/>
  </joint>

  <joint name="joint_arm_01" type="revolute">
    <parent link="servo_bottom"/>
    <child link="U_Link"/>
    <axis xyz="0 0 1"/>
    <limit effort="1000.0" lower="-3.14" upper="3.14" velocity="0.5"/>
    <origin xyz="0 0 0.056"/>
  </joint>

  <joint name="joint_arm_02" type="revolute">
    <parent link="U_Link"/>
    <child link="servo_mid"/>
    <axis xyz="0 1 0"/>
    <limit effort="1000.0" lower="-1.57" upper="1.57" velocity="0.5"/>
    <origin xyz="0 0 0.036" rpy="0 0 0"/>
  </joint>

  <joint name="servo_mid_to_servo_up" type="fixed">
    <parent link="servo_mid"/>
    <child link="servo_up"/>
    <origin xyz="0 0 0.0237" rpy="0 1.57 0"/>
  </joint>

  <joint name="joint_arm_03" type="revolute">
    <parent link="servo_up"/>
    <child link="up_mount"/>
    <axis xyz="1 0 0"/>
    <limit effort="1000.0" lower="-1.57" upper="1.57" velocity="0.5"/>
    <origin xyz="-0.028 0 0" rpy="0 -1.57 0"/>
  </joint>

  <joint name="mount_to_camera" type="fixed">
    <parent link="up_mount"/>
    <child link="camera_link"/>
    <origin xyz="0.035 0 0" rpy="0 0 0"/>
  </joint>

  <transmission name="joint_arm_01_trans">
	<type>transmission_interface/SimpleTransmission</type>
	<joint name="joint_arm_01">
		<hardwareInterface>hardware_interface/EffortJointInterface</hardwareInterface>
	</joint>
	<actuator name="motor1">
		<hardwareInterface>hardware_interface/EffortJointInterface</hardwareInterface>
		<mechanicalInterface>1</mechanicalInterface>
	</actuator>
</transmission>

<transmission name="joint_arm_02_trans">
	<type>transmission_interface/SimpleTransmission</type>
	<joint name="joint_arm_02">
		<hardwareInterface>hardware_interface/EffortJointInterface</hardwareInterface>
	</joint>
	<actuator name="motor2">
		<hardwareInterface>hardware_interface/EffortJointInterface</hardwareInterface>
		<mechanicalInterface>1</mechanicalInterface>
	</actuator>
</transmission>

<transmission name="joint_arm_03_trans">
	<type>transmission_interface/SimpleTransmission</type>
	<joint name="joint_arm_03">
		<hardwareInterface>hardware_interface/EffortJointInterface</hardwareInterface>
	</joint>
	<actuator name="motor3">
		<hardwareInterface>hardware_interface/EffortJointInterface</hardwareInterface>
		<mechanicalInterface>1</mechanicalInterface>
	</actuator>
</transmission>



</robot>
